package future;

import java.util.Random;
import java.util.concurrent.ExecutionException;
import java.util.concurrent.ExecutorService;
import java.util.concurrent.Executors;
import java.util.concurrent.Future;

/**
 * desc: 演示get方法过程中抛出异常，for循环为了演示抛出Exception的时机，并不是说一产生异常就抛出，知道我们get执行时，才抛出
 */
public class GetException {

    public static void main(String[] args) {
        ExecutorService service = Executors.newFixedThreadPool(20);
        Future<Integer> future = service.submit(() -> {
            throw new IllegalArgumentException("Callable抛出异常");
        });

        try {
            for (int i = 0; i < 5; i++) {
                System.out.println(i);
                Thread.sleep(500);
            }
            System.out.println(future.isDone());
            future.get();
        } catch (InterruptedException e) {
            e.printStackTrace();
            System.out.println("InterruptedException异常");
        } catch (ExecutionException e) {
            e.printStackTrace();
            System.out.println("ExecutionException异常");
        }
    }
}
